Workbook

Sheet Chinh cho 3 phong
C1: Đài Truyền Hình TPHCM
C2: Trung Tâm Phát hình
F4: BIÊN BẢN BÀN GIAO QUẢN LÝ TÀI SẢN
A6: STT | B6: Số chứng từ | C6: Ngày chứng từ | D6: Số hiệu cũ | E6: Số hiệu | F6: Tên tài sản | G6: Nước SX | H6: ĐVT | I6: SL | J6: Giá trị | K6: Phòng | L6: Người QL | M6: Vị trí
A7: 1 | B7: 04DA/2009 | C7: 40024 | E7: 3010101052001 | F7: Bộ Prompter Control và Tele-prompter | H7: Bộ | I7: 1 | J7: 593040360 | K7: KT | L7: TL | M7: Củ Chi
A8: 1.1 | E8: 3010101052001001 | F8: Máy vi tính, Rackmount Kit:Intel PD 925 (3.0/800/2x2MB), 256 MB PC2-5300 (DDR2-667), 80GB SATA 3.0Gb/s, Integrated Broadcom NetXtreme Gigabit Ethernet NIC, Free DOS software, FDD 1.44MB., Model:DC5700, No:SGH7040B7R | I8: 1 | J8: 0 | K8: KT | L8: TL | M8: Củ Chi
A9: 1.2 | E9: 3010101052001002 | F9: Màn hình 17", No:CNN7022TQR | I9: 1 | J9: 0 | K9: KT | L9: TL | M9: Củ Chi
A10: 1.3 | E10: 3010101052001003 | F10: 15" TFT Flat screen On-Camera monitor inclusive Integral Cue Light & external, Standard Hood with glass & light shield, 'Light weight Adjustable Mounting plate MT/RED, PCI Promptcard with Newsroom interface Winplus & Opto Desk Top Hand Control PCI/WIN/HCI. | I10: 1 | J10: 0 | K10: KT | L10: TL | M10: Củ Chi
A11: 3 | B11: 77/2009 | C11: 40178 | E11: 3010101064002 | F11: Server Capture Digital Future theo định dạng DV và MPEG-2 , Model:i-Capture, No:0787 | G11: Việt Nam | H11: Bộ | I11: 1 | J11: 224486622 | K11: PH | L11: Lam | M11: Máy VP trong lầu 1 PH mới
A12: 3.1 | E12: 3010101064002001 | F12: Màn hình vi tính LCD Viewsonic 17", Model:VA1916W, No:RN7094300049 | I12: 1 | J12: 0 | K12: PH | L12: Lam
A13: 4 | B13: 15/2011 | C13: 40702 | E13: 3010101077001 | F13: Hệ thống chạy chữ Autoscript, Model:TFT15-ELP, No:15E2101005 | G13: Anh | H13: Bộ | I13: 1 | J13: 385639606 | K13: KT | L13: TL | M13: Củ Chi
A14: 4.1 | E14: 3010101077001001 | F14: Máy vi tính chạy chữ Việt Đông | I14: 1 | J14: 12894230 | K14: KT | L14: TL | M14: Củ Chi
A15: 4.2 | E15: 3010101077001002 | F15: Màn hình LCD 17" HP, Model:LE1711, No:3Xuân00113W5 | I15: 1 | J15: 0 | K15: KT | L15: TL | M15: Củ Chi
A16: 5 | B16: 03 DA/2011 | C16: 40875 | E16: 3010101086001 | F16: Máy chủ quản lý dữ liệu File server -Media File Directory server, MediaLibrary File Directory Server, consists of redundant pair of servers, heartbeat interconnect cables, documentation, software. For use with MediaLibrary 24000e or MediaLibrary ML1G (1 bộ gồm 02 cái), Model:TLA-5001-00, No:BZDR72550962, BZDR72652478 | G16: Mỹ | H16: Bộ | I16: 1 | J16: 367831511 | K16: PH | L16: Khanh | M16: BZDR72652478 (PM.mới) Webserver cũ BZDR72550962 (PM.cũ)
A17: 6 | B17: 03 DA/2011 | C17: 40875 | E17: 3010101087001 | F17: Máy tính điều khiển tủ: PCS Server | H17: Bộ | I17: 1 | J17: 317721303 | K17: PH | L17: Khanh | M17: PM.CŨ Sony Petasite
A18: 6.1 | E18: 3010101087001001 | F18: Máy tính điều khiển tủ: PCS Server'. CPU Quad Core Xeon 5420 (2.50GHz). 'Memory: 2 GB Memory Kit. 'FDD: 1 x FDD, HP 2x 146GB SAS 10K 2.5 DP HDD, 'Optical Drive: 1 x DVD-ROM, 'Keyboard and Mouse. 'Redundant P/S: 1 Redundant Power Supply và phần mềm , Model:DL 360G5, No:SGH848XNAT | I18: 1 | J18: 243712689 | K18: PH | L18: Khanh
A19: 6.2 | E19: 3010101087001002 | F19: 17" LCD Monitor, Model:L1710, No:3Xuân8294VN6 | I19: 1 | J19: 8407751 | K19: PH | L19: Khanh
A20: 7 | B20: 03 DA/2011 | C20: 40875 | E20: 3010101088001 | F20: Server hardware for database | H20: Bộ | I20: 1 | J20: 339581457 | K20: PH | L20: Khanh | M20: PM.MỚI SQL.BK
A21: 7.1 | E21: 3010101088001001 | F21: Monitor LCD 19", Model:L1910, No:CNC820PW49 | I21: 1 | J21: 14573436 | K21: PH | L21: Khanh
A22: 7.2 | E22: 3010101088001002 | F22: Server hardware for Database: Quad Core Xeon 5420 (2.50GHz), RAM 2GB, 2 x HP 146GB 10K SAS 2.5 DP HDD; HP Slim 8X/24X DVD-ROM Drive, FDDKeyboard and Mouse, Model:DL360G5, No:GH848XNAS | I22: 1 | J22: 166361375 | K22: PH | L22: Khanh
A23: 8 | B23: 03 DA/2011 | C23: 40875 | E23: 3010101088002 | F23: Server hardware for database | H23: Bộ | I23: 1 | J23: 339581457 | K23: PH | L23: Khanh | M23: PM.Mới SQL.Main
A24: 8.1 | E24: 3010101088002001 | F24: Monitor LCD 19", Model:L1910, No:CNC820PWBM | I24: 1 | J24: 14573436 | K24: PH | L24: Khanh
A25: 8.2 | E25: 3010101088002002 | F25: Server hardware for Database: Quad Core Xeon 5420 (2.50GHz), RAM 2GB, 2 x HP 146GB 10K SAS 2.5 DP HDD; HP Slim 8X/24X DVD-ROM Drive, FDDKeyboard and Mouse, Model:DL360G5, No:GH848XNAV | I25: 1 | J25: 166361375 | K25: PH | L25: Khanh
A26: 9 | B26: 03 DA/2011 | C26: 40875 | E26: 3010101089001 | F26: Hệ thống phần cứng | H26: Bộ | I26: 1 | J26: 209765774 | K26: PH | L26: Khanh | M26: Auto9B HTV9 Bkup, PM.cũ Rack 3
A27: 9.1 | E27: 3010101089001001 | F27: PC hardware for Automation: Xeon 5450 3.00 12M/1333 QC, NVIDIA Quadro FX3700 512MB PCIe GraphicsHP 4GB (2x2GB) DDR2-667 ECC FBD RAM; HP 250GB SATA 3Gb/s . NXuân 7200 1st HDD; HP USB Standard Keyboard; HP USB Optical Scroll Mouse, HP 16X DVD+-RW SuperMulti SATA 1st Drive; Floppy Disk Drive, Model:XW8600, No:SGH85101P2 | I27: 1 | J27: 129591475 | K27: PH | L27: Khanh
A28: 9.2 | E28: 3010101089001002 | F28: 19" LCD monitor, Model:L-1910, No:CNC820PW40 | I28: 1 | J28: 14573436 | K28: PH | L28: Khanh
A29: 10 | B29: 03 DA/2011 | C29: 40875 | E29: 3010101089002 | F29: Hệ thống phần cứng | H29: Bộ | I29: 1 | J29: 209765774 | K29: PH | L29: Khanh | M29: PM.Mới
A30: 10.1 | E30: 3010101089002001 | F30: PC hardware for Automation: Xeon 5450 3.00 12M/1333 QC, NVIDIA Quadro FX3700 512MB PCIe GraphicsHP 4GB (2x2GB) DDR2-667 ECC FBD RAM; HP 250GB SATA 3Gb/s . NXuân 7200 1st HDD; HP USB Standard Keyboard; HP USB Optical Scroll Mouse, HP 16X DVD+-RW SuperMulti SATA 1st Drive; Floppy Disk Drive, Model:XW8600, No:SGH85101P1 | I30: 1 | J30: 129591475 | K30: PH | L30: Khanh
A31: 10.2 | E31: 3010101089002002 | F31: 19" LCD monitor, Model:L-1910, No:CNC820PWBL | I31: 1 | J31: 14573436 | K31: PH | L31: Khanh
A32: 11 | B32: 03 DA/2011 | C32: 40875 | E32: 3010101089003 | F32: Hệ thống phần cứng | H32: Bộ | I32: 1 | J32: 209765774 | K32: PH | L32: Khanh | M32: Kho Lầu 2
A33: 11.1 | E33: 3010101089003001 | F33: PC hardware for Automation: Xeon 5450 3.00 12M/1333 QC, NVIDIA Quadro FX3700 512MB PCIe GraphicsHP 4GB (2x2GB) DDR2-667 ECC FBD RAM; HP 250GB SATA 3Gb/s . NXuân 7200 1st HDD; HP USB Standard Keyboard; HP USB Optical Scroll Mouse, HP 16X DVD+-RW SuperMulti SATA 1st Drive; Floppy Disk Drive, Model:XW8600, No:SGH85101P5 | I33: 1 | J33: 129591475 | K33: PH | L33: Khanh
A34: 11.2 | E34: 3010101089003002 | F34: 19" LCD monitor, Model:L-1910, No:CNC820PW43 | I34: 1 | J34: 14573436 | K34: PH | L34: Khanh
A35: 12 | B35: 03 DA/2011 | C35: 40875 | E35: 3010101089005 | F35: Hệ thống phần cứng | H35: Bộ | I35: 1 | J35: 209765774 | K35: PH | L35: Khanh | M35: PM.mới
A36: 12.1 | E36: 3010101089005001 | F36: PC hardware for Automation: Xeon 5450 3.00 12M/1333 QC, NVIDIA Quadro FX3700 512MB PCIe GraphicsHP 4GB (2x2GB) DDR2-667 ECC FBD RAM; HP 250GB SATA 3Gb/s . NXuân 7200 1st HDD; HP USB Standard Keyboard; HP USB Optical Scroll Mouse, HP 16X DVD+-RW SuperMulti SATA 1st Drive; Floppy Disk Drive, Model:XW8600, No:SGH85101P3 | I36: 1 | J36: 129591475 | K36: PH | L36: Khanh
A37: 13 | B37: 03 DA/2011 | C37: 40875 | E37: 3010101089006 | F37: Hệ thống phần cứng | H37: Bộ | I37: 1 | J37: 209765775 | K37: PH | L37: Khanh | M37: PM.mới
A38: 13.1 | E38: 3010101089006001 | F38: PC hardware for Automation: Xeon 5450 3.00 12M/1333 QC, NVIDIA Quadro FX3700 512MB PCIe GraphicsHP 4GB (2x2GB) DDR2-667 ECC FBD RAM; HP 250GB SATA 3Gb/s . NXuân 7200 1st HDD; HP USB Standard Keyboard; HP USB Optical Scroll Mouse, HP 16X DVD+-RW SuperMulti SATA 1st Drive; Floppy Disk Drive, Model:XW8600, No:SGH85101P6 | I38: 1 | J38: 129591475 | K38: PH | L38: Khanh
A39: 14 | B39: 03 DA/2011 | C39: 40875 | E39: 3010101089008 | F39: Hệ thống phần cứng | H39: Bộ | I39: 1 | J39: 105621760 | K39: PH | L39: Khanh | M39: ingest 1, Kho Lầu 1
A40: 14.1 | E40: 3010101089008001 | F40: PC hardware for AutomationPentium Dual Core E2200 2.2GHz/ G33 Express Chipset/(2* 512MB)=1GB DDR2 800Mhz SDRAM/ 160GB SATA/ DVD R/W+/ No FDD, Win Vista Biz License Preloaded with Win XP Professional, mouse and keyboard, Model:DX2710, No:SGH90307TC | I40: 1 | J40: 31613146 | K40: PH | L40: Khanh
A41: 15 | B41: 03 DA/2011 | C41: 40875 | E41: 3010101089014 | F41: Hệ thống phần cứng | H41: Bộ | I41: 1 | J41: 105621760 | K41: PH | L41: Khanh | M41: Alarm K79, phía sau máy VP1
A42: 15.1 | E42: 3010101089014001 | F42: PC hardware for AutomationPentium Dual Core E2200 2.2GHz/ G33 Express Chipset/(2* 512MB)=1GB DDR2 800Mhz SDRAM/ 160GB SATA/ DVD R/W+/ No FDD, Win Vista Biz License Preloaded with Win XP Professional, mouse and keyboard, Model:DX2710, No:SGH9040CY7 | I42: 1 | J42: 31613146 | K42: PH | L42: Khanh
...

Sheet TSCD_XUAN
A1: Đài Phát Thanh - Truyền Hình TP.HCM
B2: Trung Tâm Phát hình - Tư liệu
C4: BIÊN BẢN BÀN GIAO QUẢN LÝ TÀI SẢN Chịu trách nhiệm chính: ……………………………………. Chịu trách nhiệm phụ: ……………………………..
A6: STT | B6: Ngày chứng từ | C6: Số hiệu | D6: Tên tài sản | E6: Nước SX | F6: ĐVT | G6: SL | H6: Giá trị | I6: Phòng | J6: Người QL | K6: Vị trí | M6: Kiểm tra Text | N6: Tình trạng
A7: 29 | B7: 41635 | C7: 3010101096005 | D7: Máy capture file Digital Future ((loại 2 kênh)), Model:i-capture, No:0712 | E7: Việt Nam | F7: Bộ | G7: 1 | H7: 254478351 | I7: KT | J7: Xuân | K7: A2-R6 Linux | M7: TRUE | N7: Còn
A8: 36 | B8: 41542 | C8: 3010101107004 | D8: Máy tính duyệt file Digital Future, Model:i-Check, No:40030 | E8: Việt Nam | F8: Bộ | G8: 1 | H8: 59900000 | I8: KT | J8: Xuân | K8: phtkt bàn HA quản lý CPU, a Việt giữ màn hình | M8: TRUE | N8: Còn
A9: 40 | B9: 41635 | C9: 3010101112002 | D9: Phần cứng máy chủ HP ((Server quản lý đồ họa Kernel Controller/WASP3D)), Model:DL160 G6, No:CN7238090P | E9: Singapore | F9: Bộ | G9: 1 | H9: 236609694 | I9: KT | J9: Xuân | K9: Mcr cũ - Wasp KC | M9: TRUE | N9: Còn
A10: 42 | B10: 41193 | C10: 3010101115001 | D10: Máy tính Worsktation HP (Hệ thống đồ họa: nguồn HP Z800 850W, MS Windows 7 Professional 64,CPU Intel Xeon X56723.20 12MB/1333 4C. CPU1. RAM: HP4GB (4x1GB)DDR3-1333ECC 1-CPU. Graphic card : ATI Radeon HD 6970 2GB PCIe . HDD: HP 320GB SATA 7200, 1st. HP USB standard keyboard. HP USB Optical Sccroll Mouse. HP 16X DVD+/-RW Super Multi SATA, 1stODD. HP Air Cooling Solution), Model:Z800, No:SGH213T2N2 | E10: Singapore | F10: Bộ | G10: 1 | H10: 932830700 | I10: KT | J10: Xuân | K10: A2-R6, wasp server | M10: TRUE | N10: Còn
A11: 44 | B11: 41193 | C11: 3010101116001 | D11: Máy tính Worsktation HP (Hệ thống điều khiển: nguồn HP Z200 320W, Graphics cardATI Fire Pro V4800 1GB. HDD: HP 250GB SATA 7200, 1st. HP USB standard keyboard. HP USB Optical Sccroll Mouse. OS MS Windows 7 Profestional 64 bit có bản quyền . HP 16X DVD+ RW Super Multi SATA 1st Drive. CPU Intel Xeon X3430 2.40 8MB+B70/1333QC. Windows 7 OS WW Recovery Media RAM HP 2GB (2x1GB)DDR3-1333 nECC), Model:Z210, No:SGH213T2N1 | E11: Singapore | F11: Bộ | G11: 1 | H11: 115933734 | I11: KT | J11: Xuân | K11: A2-R6: Wasp client | M11: TRUE | N11: Còn
A12: 60.2 | C12: 3010101129001002 | D12: Bộ làm trễ âm thanh Hotronic, Model:AU51D, No:51243 | G12: 1 | H12: 0 | I12: KT | J12: Xuân | K12: A2-Control trên Rack: bộ làm trễ tiếng | M12: TRUE | N12: Còn
A13: 71.4 | C13: 3010101158001004 | D13: 20" monitor LCD LV-2011, Model:HP-LV2011, No:CNC308PW59 | E13: Trung Quốc | F13: Cái | G13: 1 | H13: 0 | I13: KT | J13: Xuân | K13: A2-Control trên rack -kho | M13: TRUE | N13: Còn
A14: 143 | B14: 43256 | C14: 3010102389002 | D14: Máy tính HP (chuyên dụng cho thiết kế phim trường ảo - kèm Màn hình, card xuất hình), Model:Z640, No:SGH748TN46 | E14: Singapore | F14: Bộ | G14: 1 | H14: 389452666 | I14: KT | J14: Xuân | K14: F1 Infinity | M14: TRUE | N14: Còn
A15: 143.1 | C15: 3010102389002001 | D15: Màn hình HP 24", Model:Z24n, No:CN4745028V | E15: Trung Quốc | F15: Cái | G15: 1 | H15: 14892045 | I15: KT | J15: Xuân | K15: pHTKT: màn hình Hàn | M15: TRUE | N15: Còn
A16: 143.2 | C16: 3010102389002002 | D16: Card xuất hình AJA, Model:Corvid 88-T, No:U04758 | E16: Mỹ | F16: Cái | G16: 1 | H16: 102395650 | I16: KT | J16: Xuân | K16: F1 Infinity card trong CPU | M16: TRUE | N16: Còn
A17: 173 | B17: 43256 | C17: 3010202036004 | D17: Swich mạng Cisco, Model:WS-C2960X-24TS-LL, No:FCW2146A2ZN | E17: Trung Quốc | F17: Cái | G17: 1 | H17: 34611169 | I17: KT | J17: Xuân | K17: A2-R6 | M17: TRUE | N17: Còn
A18: 194 | B18: 36160 | C18: 3010502006001 | D18: Rắc đặt thiết bị | F18: Cái | G18: 1 | H18: 44585475 | I18: KT | J18: Xuân | K18: A2-Kho | M18: TRUE | N18: Còn
A19: 194.1 | C19: 3010502006001001 | D19: Control and monitor rack W/AC power | G19: 1 | I19: KT | J19: Xuân | K19: A2-Kho chung với Rack | M19: TRUE | N19: Còn
A20: 199 | B20: 40639 | C20: 3020302005001 | D20: Hệ thống camera IP cho khu vực kỹ thuật | F20: Hệ thống | G20: 1 | H20: 153553733 | I20: KT | J20: Xuân | K20: A2 | M20: TRUE | N20: Còn
A21: 199.1 | C21: 3020302005001001 | D21: Camera IP ACTi bán cầu hồng ngoại ngày đêm loại trong nhà, Model:ACM-3511, No:ACM3511-10E-X-00638 | G21: 1 | H21: 12862200 | I21: KT | J21: Xuân | K21: F1 CONTROL | M21: TRUE | N21: Còn
A22: 199.2 | C22: 3020302005001002 | D22: Camera IP ACTi bán cầu hồng ngoại ngày đêm loại trong nhà, Model:ACM-3511, No:ACM3511-10E-X-00639 | G22: 1 | H22: 12862200 | I22: KT | J22: Xuân | K22: MCR CŨ | M22: TRUE | N22: Còn
A23: 199.3 | C23: 3020302005001003 | D23: Camera IP ACTi bán cầu hồng ngoại ngày đêm loại trong nhà, Model:ACM-3511, No:ACM3511-10E-X-00598 | G23: 1 | H23: 12862200 | I23: KT | J23: Xuân | K23: A2 control rack audio | M23: TRUE | N23: Còn
A24: 199.4 | C24: 3020302005001004 | D24: Camera IP ACTi bán cầu hồng ngoại ngày đêm loại trong nhà, Model:ACM-3511, No:ACM3511-10E-X-00602 | G24: 1 | H24: 12862200 | I24: KT | J24: Xuân | K24: A1 PHÒNG HIỆN | M24: TRUE | N24: Còn
A25: 199.5 | C25: 3020302005001005 | D25: Camera IP ACTi bán cầu hồng ngoại ngày đêm loại trong nhà, Model:ACM-3511, No:ACM3511-10E-X-00632 | G25: 1 | H25: 12862200 | I25: KT | J25: Xuân | K25: A2 PHÒNG HIỆN | M25: TRUE | N25: Còn
A26: 199.6 | C26: 3020302005001006 | D26: Camera IP ACTi bán cầu hồng ngoại ngày đêm loại trong nhà, Model:ACM-3511, No:ACM3511-10E-X-00633 | G26: 1 | H26: 12862200 | I26: KT | J26: Xuân | K26: MCR CŨ | M26: TRUE | N26: Còn
A27: 199.1 | C27: 3.0203E+15 | D27: Màn hình vi tính HP LCD 23", No:CNC0220CLG | G27: 1 | H27: 0 | I27: KT | J27: Xuân | K27: CQ mang theo khi qua phòng Tư liệu | M27: TRUE | N27: Còn
A28: 201 | B28: 39994 | C28: 302030502008010 | D28: Bảng điều khiển 10 nút nhấn 1RU, Model:ICS-102T, No:801161 | E28: Mỹ | F28: Cái | G28: 1 | H28: 60254203 | I28: KT | J28: Xuân | K28: A2-kho: Intercom Matrix Plus | M28: TRUE | N28: Còn
A29: 229 | B29: 41274 | C29: 302030503003001 | D29: Đầu Ghi Hình Kỹ Thuật Số Supermicro, Model:CSE-822, No:C82200B32M20131 | E29: Trung Quốc | F29: Bộ | G29: 1 | H29: 65131148 | I29: KT | J29: Xuân | K29: MCR cũ, Cam quan sát | M29: TRUE | N29: Còn
A30: 229.1 | C30: 302030503003001001 | D30: PHẦN MỀM GHI HÌNH QUẢN L Ý CAMERA ACTi 32 KÊNH, Model:NVR v2.3 Enterprise | G30: 1 | H30: 25000000 | I30: KT | J30: Xuân | K30: soft | M30: TRUE | N30: Còn
A31: 232 | B31: 36160 | C31: 302099901028001 | D31: Bộ kiểm thính audio | F31: Bộ | G31: 1 | H31: 48231975 | I31: KT | J31: Xuân | K31: A2-control: Rack | M31: TRUE | N31: Còn
A32: 232.1 | C32: 302099901028001001 | D32: Bộ khuếch đại âm thanh (Audio power amplifier amcron), Model:Amcron | G32: 1 | I32: KT | J32: Xuân | K32: A2-control: Rack | M32: TRUE | N32: Còn
A33: 233 | B33: 41983 | C33: 302099901188001 | D33: Audio mixer 24 đường vào-Soundcraft, Model:GB8, No:RW5695SM151571 | E33: Trung Quốc | F33: Bộ | G33: 1 | H33: 123652652 | I33: KT | J33: Xuân | K33: TTPH-Kho lầu 2 | M33: TRUE | N33: Còn
A34: 257 | B34: 39994 | C34: 302099902619005 | D34: Bộ chuyển đổi qua lại (Bi directional AD/DA) tín hiệu hình tiếng tương tự và tín hiệu số , Model:Multibridge, No:90618 | F34: Cái | G34: 1 | H34: 38725405 | I34: KT | J34: Xuân | K34: A2-R8: BM3 | M34: TRUE | N34: Còn
A35: 262 | B35: 40352 | C35: 302099902666001 | D35: Bộ chuyển mạch số 16x16 Leitch, Model:P16X16SIE, No:LHTI0463076002 | E35: Canada | F35: Bộ | G35: 1 | H35: 433862205 | I35: KT | J35: Xuân | K35: A1-R4 | M35: TRUE | N35: Còn
A36: 262.1 | C36: 302099902666001001 | D36: Bộ điều khiển 16x1 Leitch cho Bộ chuyển mạch số 16x16 Leitch, Model:RCP-16X1P, No:LHTI0470933003 | G36: 1 | H36: 21916668 | I36: KT | J36: Xuân | K36: A2-Kho: rack (remote) | L36: đề nghị thanh lý | M36: TRUE | N36: Còn
A37: 262.2 | C37: 302099902666001002 | D37: Bộ điều khiển 16x1 Leitch cho Bộ chuyển mạch số 16x16 Leitch, Model:RCP-16X1P, No:LHTI0470935004 | G37: 1 | H37: 21916668 | I37: KT | J37: Xuân | K37: A2-Kho: rack (remote) | L37: đề nghị thanh lý | M37: TRUE | N37: Còn
A38: 262.3 | C38: 302099902666001003 | D38: Bộ điều khiển 16x1 Leitch cho Bộ chuyển mạch số 16x16 Leitch, Model:RCP-16X1P, No:LHTI0470933005 | G38: 1 | H38: 21916668 | I38: KT | J38: Xuân | K38: A2-Kho: rack (remote) | L38: đề nghị thanh lý | M38: TRUE | N38: Còn
A39: 262.4 | C39: 302099902666001004 | D39: Bộ điều khiển 16x1 Leitch cho Bộ chuyển mạch số 16x16 Leitch, Model:RCP-16X1P, No:LHTI0470935010 | G39: 1 | H39: 21916670 | I39: KT | J39: Xuân | K39: A2-Kho: rack (remote) | L39: đề nghị thanh lý | M39: TRUE | N39: Còn
A40: 269 | B40: 40948 | C40: 302099902707001 | D40: Bộ xử lý tín hiệu số Harris , Model:X50, No:LHTI2111159309 | E40: Canada | F40: Bộ | G40: 1 | H40: 268070586 | I40: KT | J40: Xuân | K40: A2-R8: x50-1 | M40: TRUE | N40: Còn
A41: 271.1 | C41: 302099902710003001 | D41: Monitor LCD 20" Samsung, Model:B2030, No:1457HYTB200367Z | G41: 1 | H41: 0 | I41: KT | J41: Xuân | K41: A2-Control, màn hình Prompter | M41: TRUE | N41: Còn
A42: 272 | B42: 41044 | C42: 302099902714001 | D42: Bộ trộn âm thanh analog Soundcraft 24 đường vào , Model:GB8, No:RW5695SM151504 | E42: Trung Quốc | F42: Bộ | G42: 1 | H42: 112936000 | I42: KT | J42: Xuân | K42: TTPH-Kho lầu 2 | L42: KIỂM 4/23 | M42: TRUE | N42: Còn
...

Sheet CCDC_XUAN
D1: Đài Phát Thanh - Truyền Hình TPHCM
D2: Đơn vị: Trung tâm Phát hình - Tư liệi
E4: BIÊN BẢN BÀN GIAO QUẢN LÝ CÔNG CỤ DỤNG CỤ
E5: Chịu trách nhiệm chính: Lý Hàn | F5: Chịu trách nhiệm phụ: Bùi Việt Hưng
A7: STT | B7: Số chứng từ | C7: Ngày chứng từ | D7: Ký hiệu | E7: TÊN CCDC | F7: Serial | G7: Nước SX | H7: ĐVT | I7: SL | J7: Nguyên giá | K7: Giá trị ban đầu | L7: Giá trị còn lại trước phân bổ kỳ báocáo | M7: Tỷ lệ PB kỳ BC | N7: Giá trị phân bổ đến kỳ báo cáo | O7: Giá trị còn lại đến kỳ báocáo | P7: Nơi đặt để | Q7: Phòng | R7: Người quản lý | S7: Chỗ đặt | U7: STT ĐẾM MÓN | V7: CHECK TEXT | W7: So với file CCDC TC gởi
A8: 1 | B8: 40817 | C8: 40640 | D8: 3010102337034 | E8: Máy tính desktop Dell | F8: GX3372S | G8: Malaysia | H8: Bộ | I8: 1 | J8: 15582606 | K8: 8830146 | L8: 0 | M8: 0 | N8: 0 | O8: 0 | Q8: PH | R8: Khanh | S8: Củ Chi, chưa thanh lý màn hình | U8: 1 | V8: TRUE | W8: Còn
A9: 2 | B9: 41275 | C9: 41326 | D9: 3010102361034 | E9: Máy tính desktop Dell | F9: CX3VD2S | G9: Malaysia | H9: Bộ | I9: 1 | J9: 21510000 | K9: 20076000 | L9: 0 | M9: 0 | N9: 0 | O9: 0 | Q9: KT | R9: HA | S9: Đã thanh lý CPU, còn chi tiết màn hình trên tủ hồ sơ | U9: 2 | V9: TRUE | W9: Còn
A10: 3 | B10: 41275 | C10: 41326 | D10: 3010102361035 | E10: Máy tính desktop Dell | F10: 7W3VD2S | G10: Malaysia | H10: Bộ | I10: 1 | J10: 21510000 | K10: 20076000 | L10: 0 | M10: 0 | N10: 0 | O10: 0 | Q10: PH | R10: Khanh | S10: Củ Chi, Tài chính chưa trừ, thiếu MH??? | U10: 3 | V10: TRUE | W10: Còn
A11: 4 | B11: 41275 | C11: 41326 | D11: 3010102361036 | E11: Máy tính desktop Dell | F11: 2Y3VD2S | G11: Malaysia | H11: Bộ | I11: 1 | J11: 21510000 | K11: 20076000 | L11: 0 | M11: 0 | N11: 0 | O11: 0 | Q11: MCR | R11: Tâm | S11: PH - Sát vách kính | U11: 4 | V11: TRUE | W11: Còn
A12: 5 | B12: 41275 | C12: 41326 | D12: 3010102361037 | E12: Máy tính desktop Dell | F12: 1X3VD2S | G12: Malaysia | H12: Bộ | I12: 1 | J12: 21510000 | K12: 20076000 | L12: 0 | M12: 0 | N12: 0 | O12: 0 | Q12: MCR | R12: Tâm | S12: Bàn 2 | U12: 5 | V12: TRUE | W12: Còn
A13: 6 | B13: 41275 | C13: 41326 | D13: 3010102361038 | E13: Máy tính desktop Dell | F13: 2X3VD2S | G13: Malaysia | H13: Bộ | I13: 1 | J13: 21510000 | K13: 20076000 | L13: 0 | M13: 0 | N13: 0 | O13: 0 | Q13: KT | R13: QUAN | S13: CPU máy Quân | U13: 6 | V13: TRUE | W13: Còn
A14: 7 | B14: 41275 | C14: 41326 | D14: 3010102361039 | E14: Máy tính desktop Dell | F14: 6W3VD2S | G14: Malaysia | H14: Bộ | I14: 1 | J14: 21510000 | K14: 20076000 | L14: 0 | M14: 0 | N14: 0 | O14: 0 | Q14: MCR | R14: Tâm | S14: Linux (upload file) | U14: 7 | V14: TRUE | W14: Còn
A15: 8 | B15: 23/2011 | C15: 40743 | D15: 3010103057001 | E15: Máy tính xách tay Sony | F15: 275329777000158 | G15: Trung Quốc | H15: Cái | I15: 1 | J15: 29545455 | K15: 18219703 | L15: 0 | M15: 0 | N15: 0 | O15: 0 | Q15: GD | R15: Đình Lâm | S15: phòng sếp Lâm | U15: 8 | V15: TRUE | W15: Còn
A16: 9 | B16: 03Da01 | C16: 36892 | D16: 3010104056007 | E16: Monitor 10" PVM- 9045QM | F16: 2003009 | H16: Cái | I16: 1 | J16: 14614587 | K16: 0 | L16: 0 | M16: 0 | N16: 0 | O16: 0 | Q16: KT | R16: Xuân | S16: A2 CONTROL | U16: 9 | V16: TRUE | W16: Còn
A17: 10 | B17: 05DA97 | C17: 36161 | D17: 3010104072005 | E17: Monitor 14" | F17: BF-5439 | I17: 1 | J17: 19480338 | K17: 0 | L17: 0 | M17: 0 | N17: 0 | O17: 0 | Q17: KT | R17: TL | S17: Củ Chi | T17: KT CQ thanh lý | U17: 10 | V17: TRUE | W17: Đã thanh lý/chuyển
A18: 11 | B18: 03Da04 | C18: 37987 | D18: 3010104093009 | E18: Monitor kiểm tra - 14" Color TV set | F18: 517952 | I18: 1 | J18: 3705220 | K18: 0 | L18: 0 | M18: 0 | N18: 0 | O18: 0 | P18: Điều chuyển từ QLKT 09/6/2015 | Q18: MCR | R18: Tâm | S18: PĐ1 | U18: 11 | V18: TRUE | W18: Còn
A19: 12 | B19: 28/2007 | C19: 38717 | D19: 3010104107002 | E19: Monitor LCD Display Viewsonic 17" | F19: A330 447 554 65 | I19: 1 | J19: 7042513 | K19: 0 | L19: 0 | M19: 0 | N19: 0 | O19: 0 | Q19: MCR | R19: Thi | S19: MCR | U19: 12 | V19: TRUE | W19: Còn
A20: 13 | B20: 169 | C20: 38625 | D20: 3010104113001 | E20: Monitor sony 14"( Hệ thống INEW) | F20: 2006440 | I20: 1 | J20: 21712829 | K20: 0 | L20: 0 | M20: 0 | N20: 0 | O20: 0 | P20: Điều chuyển từ QLKT 09/6/2015 | Q20: MCR | R20: Tâm | S20: Hư - Kho | U20: 13 | V20: TRUE | W20: Đã thanh lý/chuyển
A21: 14 | B21: 210 | C21: 39080 | D21: 3010104154002 | E21: Monitor LCD Viewsonic 19" | F21: QALI064524218 | I21: 1 | J21: 5060000 | K21: 0 | L21: 0 | M21: 0 | N21: 0 | O21: 0 | Q21: PH | R21: Khanh | S21: Kho lầu 2 | U21: 14 | V21: TRUE | W21: Còn
A22: 15 | B22: 211 | C22: 39080 | D22: 3010104154003 | E22: Monitor LCD Viewsonic 19" | F22: QALI064524219 | I22: 1 | J22: 5060000 | K22: 0 | L22: 0 | M22: 0 | N22: 0 | O22: 0 | Q22: PH | R22: Khanh | S22: Kho lầu 2 | U22: 15 | V22: TRUE | W22: Còn
A23: 16 | B23: 174 | C23: 39080 | D23: 3010104157001 | E23: Clour LCD monitor 17 inch | F23: PPJ062950020 | I23: 1 | J23: 4914054 | K23: 0 | L23: 0 | M23: 0 | N23: 0 | O23: 0 | Q23: PH | R23: Khanh | S23: Kho lầu 2 | U23: 16 | V23: TRUE | W23: Còn
A24: 17 | B24: 38 | C24: 39283 | D24: 3010104166001 | E24: Monitor Samsung LCD 32" | F24: 09923YHP500013J | H24: Cái | I24: 1 | J24: 15600000 | K24: 0 | L24: 0 | M24: 0 | N24: 0 | O24: 0 | P24: VPĐD HTV tại HN điều chuyển | Q24: KT | R24: TL | S24: Củ Chi | T24: KT Thanh thanh lý | U24: 17 | V24: TRUE | W24: Đã thanh lý/chuyển
A25: 18 | B25: 28/2007 | C25: 38717 | D25: 3010104167005 | E25: Màn hình kiểm tra 15" + board SDI | F25: 16905810 | G25: Thái Lan | H25: Cái | I25: 1 | J25: 13266876 | K25: 0 | L25: 0 | M25: 0 | N25: 0 | O25: 0 | Q25: KT | R25: TL | S25: Củ Chi | T25: KT CQ thanh lý | U25: 18 | V25: TRUE | W25: Đã thanh lý/chuyển
A26: 19 | B26: 28/2007 | C26: 38717 | D26: 3010104168001 | E26: 15" LCD Monitor | F26: P5 HO 44101380 | G26: Trung Quốc | H26: Cái | I26: 1 | J26: 2069440 | K26: 0 | L26: 0 | M26: 0 | N26: 0 | O26: 0 | Q26: PH | R26: Khanh | S26: kho PH lầu 2 đã hư | U26: 19 | V26: TRUE | W26: Còn
A27: 20 | B27: 28/2007 | C27: 38717 | D27: 3010104168002 | E27: 15" LCD Monitor | F27: P5 HO 44101960 | G27: Trung Quốc | H27: Cái | I27: 1 | J27: 2069440 | K27: 0 | L27: 0 | M27: 0 | N27: 0 | O27: 0 | Q27: PH | R27: Khanh | S27: Kho lầu 2 | U27: 20 | V27: TRUE | W27: Còn
A28: 21 | B28: 28/2007 | C28: 38717 | D28: 3010104168003 | E28: 15" LCD Monitor | F28: P5 HO 44101477 | G28: Trung Quốc | H28: Cái | I28: 1 | J28: 2069440 | K28: 0 | L28: 0 | M28: 0 | N28: 0 | O28: 0 | Q28: PH | R28: Khanh | S28: Kho lầu 2 | U28: 21 | V28: TRUE | W28: Còn
A29: 22 | B29: 28/2007 | C29: 38717 | D29: 3010104168004 | E29: 15" LCD Monitor | F29: P5 HO 44101958 | G29: Trung Quốc | H29: Cái | I29: 1 | J29: 2069440 | K29: 0 | L29: 0 | M29: 0 | N29: 0 | O29: 0 | Q29: PH | R29: Khanh | S29: Kho lầu 2 | U29: 22 | V29: TRUE | W29: Còn
A30: 23 | B30: 235 | C30: 38681 | D30: 3010104170002 | E30: Monitor 14" | F30: 2112348 | I30: 1 | J30: 20820034 | K30: 0 | L30: 0 | M30: 0 | N30: 0 | O30: 0 | Q30: MCR | R30: Tâm | S30: Kho | U30: 23 | V30: TRUE | W30: Đã thanh lý/chuyển
A31: 24 | B31: 03Da01 | C31: 36892 | D31: 3010104181001 | E31: Video monitor 14" | F31: 6013072 | I31: 1 | J31: 7004677 | K31: 0 | L31: 0 | M31: 0 | N31: 0 | O31: 0 | P31: Điều chuyển từ QLKT 09/6/2015 | Q31: MCR | R31: Tâm | S31: Sát tường - dùng kiểm file | U31: 24 | V31: TRUE | W31: Đã thanh lý/chuyển
A32: 25 | B32: 03Da01 | C32: 36892 | D32: 3010104181003 | E32: Video monitor 14" | F32: 6013078 | I32: 1 | J32: 7004677 | K32: 0 | L32: 0 | M32: 0 | N32: 0 | O32: 0 | P32: Điều chuyển từ QLKT 09/6/2015 | Q32: MCR | R32: Tâm | S32: Kho | U32: 25 | V32: TRUE | W32: Đã thanh lý/chuyển
A33: 26 | B33: 34/2009 | C33: 40072 | D33: 3010104187001 | E33: Màn hình vi tính LCD 17" Samsung | F33: YM17HYTS900772T | G33: Việt Nam | H33: Cái | I33: 1 | J33: 2427000 | K33: 606750 | L33: 0 | M33: 0 | N33: 0 | O33: 0 | Q33: PH | R33: Khanh | S33: Kho lầu 2 | U33: 26 | V33: TRUE | W33: Còn
A34: 27 | B34: 15/2011 | C34: 40702 | D34: 3010104195001 | E34: Màn hình LCD 20" Samsung | F34: LR20HYTZ800542L | G34: Việt Nam | H34: Cái | I34: 1 | J34: 3928717 | K34: 2357221 | L34: 0 | M34: 0 | N34: 0 | O34: 0 | Q34: KT | R34: HAN | S34: P.HTKT màn hình hư, nóc tủ hồ sơ | U34: 27 | V34: TRUE | W34: Còn
A35: 28 | B35: 15/2011 | C35: 40702 | D35: 3010104195002 | E35: Màn hình LCD 20" Samsung | F35: LR20HYTZ800503R | G35: Việt Nam | H35: Cái | I35: 1 | J35: 3928717 | K35: 2357221 | L35: 0 | M35: 0 | N35: 0 | O35: 0 | Q35: MCR | R35: Tâm | S35: MCR | U35: 28 | V35: TRUE | W35: Còn
A36: 29 | B36: 15/2011 | C36: 40702 | D36: 3010104195003 | E36: Màn hình LCD 20" Samsung | F36: LR20HYTZ800396H | G36: Việt Nam | H36: Cái | I36: 1 | J36: 3928717 | K36: 2357221 | L36: 0 | M36: 0 | N36: 0 | O36: 0 | Q36: KT | R36: TL | S36: Củ Chi | T36: Hàn thanh lý | U36: 29 | V36: TRUE | W36: Đã thanh lý/chuyển
A37: 30 | B37: 15/2011 | C37: 40702 | D37: 3010104195004 | E37: Màn hình LCD 20" Samsung | F37: LR20HYTZ800529R | G37: Việt Nam | H37: Cái | I37: 1 | J37: 3928717 | K37: 2357221 | L37: 0 | M37: 0 | N37: 0 | O37: 0 | Q37: PH | R37: Khanh | S37: Kho lầu 2 | U37: 30 | V37: TRUE | W37: Còn
A38: 31 | B38: 15/2011 | C38: 40702 | D38: 3010104195005 | E38: Màn hình LCD 20" Samsung | F38: LR20HYTZ800383H | G38: Việt Nam | H38: Cái | I38: 1 | J38: 3928717 | K38: 2357221 | L38: 0 | M38: 0 | N38: 0 | O38: 0 | Q38: KT | R38: TL | S38: Củ Chi | T38: Hàn thanh lý | U38: 31 | V38: TRUE | W38: Đã thanh lý/chuyển
A39: 32 | B39: 15/2011 | C39: 40702 | D39: 3010104195006 | E39: Màn hình LCD 20" Samsung | F39: LR20HYTZ800029X | G39: Việt Nam | H39: Cái | I39: 1 | J39: 3928717 | K39: 2357221 | L39: 0 | M39: 0 | N39: 0 | O39: 0 | Q39: KT | R39: TL | S39: Củ Chi | T39: Hàn thanh lý | U39: 32 | V39: TRUE | W39: Đã thanh lý/chuyển
A40: 33 | B40: 15/2011 | C40: 40702 | D40: 3010104195007 | E40: Màn hình LCD 20" Samsung | F40: LR20HYTZ500463P | G40: Việt Nam | H40: Cái | I40: 1 | J40: 3928717 | K40: 2357221 | L40: 0 | M40: 0 | N40: 0 | O40: 0 | Q40: KT | R40: HAN | S40: P.HTKT nóc tủ hồ sơ, trong thùng | U40: 33 | V40: TRUE | W40: Còn
A41: 34 | B41: 41518 | C41: 41386 | D41: 3010104201001 | E41: Màn hình LCD 24" Asus | F41: B5LMTF064240 | G41: Trung Quốc | H41: Cái | I41: 1 | J41: 5390909 | K41: 5211213 | L41: 0 | M41: 0 | N41: 0 | O41: 0 | Q41: KT | R41: HAN | S41: bàn HA | U41: 34 | V41: TRUE | W41: Còn
A42: 35 | B42: 0024XCC/AR/DV09/2016 | C42: 42731 | D42: 30101050122027 | E42: Bộ kéo dài chuột bàn phím Aten (CE700A) | F42: F3FAO57D70524 | H42: Bộ | I42: 1 | J42: 7074438 | K42: 7074438 | L42: 0 | M42: 0 | N42: 0 | O42: 0 | Q42: PH | R42: Lam | S42: KHO | U42: 35 | V42: TRUE | W42: Còn
...

Sheet CCDC
D1: Đài Truyền Hình TPHCM
D2: Đơn vị: Trung tâm Phát hình
E4: BIÊN BẢN BÀN GIAO QUẢN LÝ CÔNG CỤ DỤNG CỤ
A7: STT | B7: Số chứng từ | C7: Ngày chứng từ | D7: Ký hiệu | E7: TÊN CCDC | F7: Serial | G7: Nước SX | H7: ĐVT | I7: SL | J7: Nguyên giá | K7: Giá trị ban đầu | L7: Giá trị còn lại trước phân bổ kỳ báocáo | M7: Tỷ lệ PB kỳ BC | N7: Giá trị phân bổ đến kỳ báo cáo | O7: Giá trị còn lại đến kỳ báocáo | P7: Nơi đặt để | Q7: Phòng | R7: Người quản lý | S7: Chỗ đặt
A8: 1 | B8: 10/2011 | C8: 40640 | D8: 3010102337034 | E8: Máy tính desktop Dell | F8: GX3372S | G8: Malaysia | H8: Bộ | I8: 1 | J8: 15582606 | K8: 8830146 | L8: 0 | M8: 0 | N8: 0 | O8: 0 | Q8: PH | R8: Khanh | S8: Chép file HTVC cũ
A9: 2 | B9: 01/2013 | C9: 41326 | D9: 3010102361034 | E9: Máy tính desktop Dell | F9: CX3VD2S | G9: Malaysia | H9: Bộ | I9: 1 | J9: 21510000 | K9: 20076000 | L9: 0 | M9: 0 | N9: 0 | O9: 0 | Q9: KT | R9: HA | S9: Đã thanh lý CPU, còn chi tiết màn hình trên tủ hồ sơ
A10: 3 | B10: 01/2013 | C10: 41326 | D10: 3010102361035 | E10: Máy tính desktop Dell | F10: 7W3VD2S | G10: Malaysia | H10: Bộ | I10: 1 | J10: 21510000 | K10: 20076000 | L10: 0 | M10: 0 | N10: 0 | O10: 0 | Q10: PH | R10: Khanh | S10: Kho lầu 1
A11: 4 | B11: 01/2013 | C11: 41326 | D11: 3010102361036 | E11: Máy tính desktop Dell | F11: 2Y3VD2S | G11: Malaysia | H11: Bộ | I11: 1 | J11: 21510000 | K11: 20076000 | L11: 0 | M11: 0 | N11: 0 | O11: 0 | Q11: MCR | R11: Tâm | S11: PH - Sát vách kính
A12: 5 | B12: 01/2013 | C12: 41326 | D12: 3010102361037 | E12: Máy tính desktop Dell | F12: 1X3VD2S | G12: Malaysia | H12: Bộ | I12: 1 | J12: 21510000 | K12: 20076000 | L12: 0 | M12: 0 | N12: 0 | O12: 0 | Q12: MCR | R12: Tâm | S12: Bàn 2
A13: 6 | B13: 01/2013 | C13: 41326 | D13: 3010102361038 | E13: Máy tính desktop Dell | F13: 2X3VD2S | G13: Malaysia | H13: Bộ | I13: 1 | J13: 21510000 | K13: 20076000 | L13: 0 | M13: 0 | N13: 0 | O13: 0 | Q13: KT | R13: QUAN | S13: CPU máy Quân
A14: 7 | B14: 01/2013 | C14: 41326 | D14: 3010102361039 | E14: Máy tính desktop Dell | F14: 6W3VD2S | G14: Malaysia | H14: Bộ | I14: 1 | J14: 21510000 | K14: 20076000 | L14: 0 | M14: 0 | N14: 0 | O14: 0 | Q14: MCR | R14: Tâm | S14: Linux (upload file)
A15: 8 | B15: 23/2011 | C15: 40743 | D15: 3010103057001 | E15: Máy tính xách tay Sony | F15: 275329777000158 | G15: Trung Quốc | H15: Cái | I15: 1 | J15: 29545455 | K15: 18219703 | L15: 0 | M15: 0 | N15: 0 | O15: 0 | Q15: GD | R15: Đình Lâm | S15: phòng sếp Lâm
A16: 9 | B16: 03Da01 | C16: 36892 | D16: 3010104056007 | E16: Monitor 10" PVM- 9045QM | F16: 2003009 | H16: Cái | I16: 1 | J16: 14614587 | K16: 0 | L16: 0 | M16: 0 | N16: 0 | O16: 0 | Q16: KT | R16: Xuân | S16: =IFERROR(VLOOKUP(D16, CCDC_XUAN!$D$16:$S$693, 16, 0), "Không tìm thấy") -> A2 CONTROL
A17: 10 | B17: 05DA97 | C17: 36161 | D17: 3010104072005 | E17: Monitor 14" | F17: BF-5439 | I17: 1 | J17: 19480338 | K17: 0 | L17: 0 | M17: 0 | N17: 0 | O17: 0 | Q17: KT | R17: TL | S17: Củ Chi | T17: KT Xuân thanh lý | U17: ok
A18: 11 | B18: 03Da04 | C18: 37987 | D18: 3010104093009 | E18: Monitor kiểm tra - 14" Color TV set | F18: 517952 | I18: 1 | J18: 3705220 | K18: 0 | L18: 0 | M18: 0 | N18: 0 | O18: 0 | P18: Điều chuyển từ QLKT 09/6/2015 | Q18: MCR | R18: Tâm | S18: PĐ1
A19: 12 | B19: 28/2007 | C19: 38717 | D19: 3010104107002 | E19: Monitor LCD Display Viewsonic 17" | F19: A330 447 554 65 | I19: 1 | J19: 7042513 | K19: 0 | L19: 0 | M19: 0 | N19: 0 | O19: 0 | Q19: MCR | R19: Thịnh | S19: MCR
A20: 13 | B20: 169 | C20: 38625 | D20: 3010104113001 | E20: Monitor sony 14"( Hệ thống INEW) | F20: 2006440 | I20: 1 | J20: 21712829 | K20: 0 | L20: 0 | M20: 0 | N20: 0 | O20: 0 | P20: Điều chuyển từ QLKT 09/6/2015 | Q20: MCR | R20: Tâm | S20: Hư - Kho
A21: 14 | B21: 210 | C21: 39080 | D21: 3010104154002 | E21: Monitor LCD Viewsonic 19" | F21: QALI064524218 | I21: 1 | J21: 5060000 | K21: 0 | L21: 0 | M21: 0 | N21: 0 | O21: 0 | Q21: PH | R21: Khanh | S21: Kho lầu 2
A22: 15 | B22: 211 | C22: 39080 | D22: 3010104154003 | E22: Monitor LCD Viewsonic 19" | F22: QALI064524219 | I22: 1 | J22: 5060000 | K22: 0 | L22: 0 | M22: 0 | N22: 0 | O22: 0 | Q22: PH | R22: Khanh | S22: Kho lầu 2
A23: 16 | B23: 174 | C23: 39080 | D23: 3010104157001 | E23: Clour LCD monitor 17 inch | F23: PPJ062950020 | I23: 1 | J23: 4914054 | K23: 0 | L23: 0 | M23: 0 | N23: 0 | O23: 0 | Q23: PH | R23: Khanh | S23: Kho lầu 2
A24: 17 | B24: 38 | C24: 39283 | D24: 3010104166001 | E24: Monitor Samsung LCD 32" | F24: 09923YHP500013J | H24: Cái | I24: 1 | J24: 15600000 | K24: 0 | L24: 0 | M24: 0 | N24: 0 | O24: 0 | P24: VPĐD HTV tại HN điều chuyển | Q24: KT | R24: TL | S24: Củ Chi | T24: KT Thanh thanh lý | U24: ok
A25: 18 | B25: 28/2007 | C25: 38717 | D25: 3010104167005 | E25: Màn hình kiểm tra 15" + board SDI | F25: 16905810 | G25: Thái Lan | H25: Cái | I25: 1 | J25: 13266876 | K25: 0 | L25: 0 | M25: 0 | N25: 0 | O25: 0 | Q25: KT | R25: TL | S25: Củ Chi | T25: KT Xuân thanh lý | U25: ok
A26: 19 | B26: 28/2007 | C26: 38717 | D26: 3010104168001 | E26: 15" LCD Monitor | F26: P5 HO 44101380 | G26: Trung Quốc | H26: Cái | I26: 1 | J26: 2069440 | K26: 0 | L26: 0 | M26: 0 | N26: 0 | O26: 0 | Q26: PH | R26: Khanh | S26: kho PH lầu 2 đã hư
A27: 20 | B27: 28/2007 | C27: 38717 | D27: 3010104168002 | E27: 15" LCD Monitor | F27: P5 HO 44101960 | G27: Trung Quốc | H27: Cái | I27: 1 | J27: 2069440 | K27: 0 | L27: 0 | M27: 0 | N27: 0 | O27: 0 | Q27: PH | R27: Khanh | S27: Kho lầu 2
A28: 21 | B28: 28/2007 | C28: 38717 | D28: 3010104168003 | E28: 15" LCD Monitor | F28: P5 HO 44101477 | G28: Trung Quốc | H28: Cái | I28: 1 | J28: 2069440 | K28: 0 | L28: 0 | M28: 0 | N28: 0 | O28: 0 | Q28: PH | R28: Khanh | S28: Kho lầu 2
A29: 22 | B29: 28/2007 | C29: 38717 | D29: 3010104168004 | E29: 15" LCD Monitor | F29: P5 HO 44101958 | G29: Trung Quốc | H29: Cái | I29: 1 | J29: 2069440 | K29: 0 | L29: 0 | M29: 0 | N29: 0 | O29: 0 | Q29: PH | R29: Khanh | S29: Kho lầu 2
A30: 23 | B30: 235 | C30: 38681 | D30: 3010104170002 | E30: Monitor 14" | F30: 2112348 | I30: 1 | J30: 20820034 | K30: 0 | L30: 0 | M30: 0 | N30: 0 | O30: 0 | Q30: MCR | R30: Tâm | S30: Kho
A31: 24 | B31: 03Da01 | C31: 36892 | D31: 3010104181001 | E31: Video monitor 14" | F31: 6013072 | I31: 1 | J31: 7004677 | K31: 0 | L31: 0 | M31: 0 | N31: 0 | O31: 0 | P31: Điều chuyển từ QLKT 09/6/2015 | Q31: MCR | R31: Tâm | S31: Sát tường - dùng kiểm file
A32: 25 | B32: 03Da01 | C32: 36892 | D32: 3010104181003 | E32: Video monitor 14" | F32: 6013078 | I32: 1 | J32: 7004677 | K32: 0 | L32: 0 | M32: 0 | N32: 0 | O32: 0 | P32: Điều chuyển từ QLKT 09/6/2015 | Q32: MCR | R32: Tâm | S32: Kho
A33: 26 | B33: 34/2009 | C33: 40072 | D33: 3010104187001 | E33: Màn hình vi tính LCD 17" Samsung | F33: YM17HYTS900772T | G33: Việt Nam | H33: Cái | I33: 1 | J33: 2427000 | K33: 606750 | L33: 0 | M33: 0 | N33: 0 | O33: 0 | Q33: PH | R33: Khanh | S33: Kho lầu 2
A34: 27 | B34: 15/2011 | C34: 40702 | D34: 3010104195001 | E34: Màn hình LCD 20" Samsung | F34: LR20HYTZ800542L | G34: Việt Nam | H34: Cái | I34: 1 | J34: 3928717 | K34: 2357221 | L34: 0 | M34: 0 | N34: 0 | O34: 0 | Q34: KT | R34: HAN | S34: P.HTKT màn hình hư, nóc tủ hồ sơ
A35: 28 | B35: 15/2011 | C35: 40702 | D35: 3010104195002 | E35: Màn hình LCD 20" Samsung | F35: LR20HYTZ800503R | G35: Việt Nam | H35: Cái | I35: 1 | J35: 3928717 | K35: 2357221 | L35: 0 | M35: 0 | N35: 0 | O35: 0 | Q35: MCR | R35: Tâm | S35: MCR
A36: 29 | B36: 15/2011 | C36: 40702 | D36: 3010104195003 | E36: Màn hình LCD 20" Samsung | F36: LR20HYTZ800396H | G36: Việt Nam | H36: Cái | I36: 1 | J36: 3928717 | K36: 2357221 | L36: 0 | M36: 0 | N36: 0 | O36: 0 | Q36: KT | R36: TL | S36: Củ Chi | T36: Hàn thanh lý | U36: ok
A37: 30 | B37: 15/2011 | C37: 40702 | D37: 3010104195004 | E37: Màn hình LCD 20" Samsung | F37: LR20HYTZ800529R | G37: Việt Nam | H37: Cái | I37: 1 | J37: 3928717 | K37: 2357221 | L37: 0 | M37: 0 | N37: 0 | O37: 0 | Q37: PH | R37: Khanh | S37: Kho lầu 2
A38: 31 | B38: 15/2011 | C38: 40702 | D38: 3010104195005 | E38: Màn hình LCD 20" Samsung | F38: LR20HYTZ800383H | G38: Việt Nam | H38: Cái | I38: 1 | J38: 3928717 | K38: 2357221 | L38: 0 | M38: 0 | N38: 0 | O38: 0 | Q38: KT | R38: TL | S38: Củ Chi | T38: Hàn thanh lý | U38: ok
A39: 32 | B39: 15/2011 | C39: 40702 | D39: 3010104195006 | E39: Màn hình LCD 20" Samsung | F39: LR20HYTZ800029X | G39: Việt Nam | H39: Cái | I39: 1 | J39: 3928717 | K39: 2357221 | L39: 0 | M39: 0 | N39: 0 | O39: 0 | Q39: KT | R39: TL | S39: Củ Chi | T39: Hàn thanh lý | U39: ok
A40: 33 | B40: 15/2011 | C40: 40702 | D40: 3010104195007 | E40: Màn hình LCD 20" Samsung | F40: LR20HYTZ500463P | G40: Việt Nam | H40: Cái | I40: 1 | J40: 3928717 | K40: 2357221 | L40: 0 | M40: 0 | N40: 0 | O40: 0 | Q40: KT | R40: HAN | S40: P.HTKT nóc tủ hồ sơ, trong thùng
A41: 34 | B41: 09/2013 | C41: 41386 | D41: 3010104201001 | E41: Màn hình LCD 24" Asus | F41: B5LMTF064240 | G41: Trung Quốc | H41: Cái | I41: 1 | J41: 5390909 | K41: 5211213 | L41: 0 | M41: 0 | N41: 0 | O41: 0 | Q41: KT | R41: HAN | S41: bàn HA
A42: 35 | B42: 0024XCC/AR/DV09/2016 | C42: 42731 | D42: 30101050122027 | E42: Bộ kéo dài chuột bàn phím Aten (CE700A) | F42: F3FAO57D70524 | H42: Bộ | I42: 1 | J42: 7074438 | K42: 7074438 | L42: 0 | M42: 0 | N42: 0 | O42: 0 | Q42: PH | R42: Lam | S42: KHO
A43: 36 | B43: 0024XCC/AR/DV09/2016 | C43: 42731 | D43: 30101050122028 | E43: Bộ kéo dài chuột bàn phím Aten (CE700A) | F43: F3FAO57D70521 | H43: Bộ | I43: 1 | J43: 7074438 | K43: 7074438 | L43: 0 | M43: 0 | N43: 0 | O43: 0 | Q43: PH | R43: Lam | S43: KHO
...

Sheet Sheet1
A1: =IFERROR(__xludf.DUMMYFUNCTION("IMPORTRANGE(""[https://docs.google.com/spreadsheets/d/187-YYbipN2LNDJnripWi4_Nwdk9k3RiVvHiNha54jYw](https://docs.google.com/spreadsheets/d/187-YYbipN2LNDJnripWi4_Nwdk9k3RiVvHiNha54jYw)"", ""Câu trả lời biểu mẫu 1!A:C"")"),"#REF!") -> #REF!
A29: 46119.728 | B29: 70109110001 | C29: Phần mềm thiết kế phim trường ảo Brainstorm, Model:InfinitySet | D29: Phòng Lầu 2 | E29: Quân
A30: 46119.738 | B30: 302099902801001 | C30: All-in-one 17" Prompter Monitor and integrated 17" On-Air Talent Monitor Autoscript, Model:EPIC17, No:EPIC 17190084 | D30: Nhà | E30: Quân
A31: 46119.749 | B31: 70109110001 | C31: Phần mềm thiết kế phim trường ảo Brainstorm, Model:InfinitySet | D31: Toilet | E31: Thanh
A32: 46119.751 | B32: 30411193004 | C32: Tivi LED 50" Sony, Model:KDL-50W704A, No:2706905 | D32: Phòng làm việc | E32: Minh Quân
A33: 46119.757 | B33: 70109110001 | C33: Phần mềm thiết kế phim trường ảo Brainstorm, Model:InfinitySet | D33: Khách | E33: Thanh
A34: 46119.758 | B34: 3020999002002 | C34: Bộ 42 nút bấm LED Snell cho bàn phím điều khiển Snell - Remote 16x16 cho Router Snell, Model:7028100RCSB, No:S711191 | D34: Xe hơi | E34: Hùng
A35: 46119.762 | B35: 3010101157001006 | C35: Máy tính điều khiển xách tay-HP, Model:PROB00K440GO, No:2CE32105B7 | D35: Phòng ngủ | E35: Cường
A36: 46119.818 | B36: 3010101158002 | C36: Bộ tạo chữ gồm máy server- phần mềm Stingserver, máy điều khiển - phần mềm StingClient. (Theo chi tiết) | D36: Ăn | E36: Tùng
A37: 46119.849 | B37: 3010101158001001 | C37: Phần cứng thiết kế đồ họa: Z620 Workstation Intel Xeon E5-1650 3.20Ghz 12MB 1600 6C; 4GB DDR3-1600 (2x2GB) 1CPU RAM; NVIDIA Quadro 4000 2GB Graphics; 1TB 7200 RPM SATA HDD; 16X SuperMulti DVDRW SATA; Windows 7 Pro Edition 64bit; bàn phím, chuột, Model:HP-Z620, No:SGH341TSL1 | D37: Kho văn phòng | E37: Hàn
A38: 46120.957 | B38: 3010101157003 | C38: Hệ thống chạy chữ (Autoscript) bao gồm:Thiết bị xuất hình và Bộ điều khiển chạy chữ (Theo chi tiết), Model:Xbox Ultra WinPlus, No:24130640 | D38: Test 1 | E38: Q
A39: 46120.962 | B39: 3010101064002 | C39: Server Capture Digital Future theo định dạng DV và MPEG-2 , Model:i-Capture, No:0787 | D39: ĐC Lam | E39: Quân
A40: 46120.966 | B40: 3010101064002 | C40: Server Capture Digital Future theo định dạng DV và MPEG-2 , Model:i-Capture, No:0787 | D40: Q | E40: Q
A41: 46120.969 | B41: 3010101064002 | C41: Server Capture Digital Future theo định dạng DV và MPEG-2 , Model:i-Capture, No:0787 | D41: Bếp | E41: Hải
A42: 46120.976 | B42: 3010101064002 | C42: Server Capture Digital Future theo định dạng DV và MPEG-2 , Model:i-Capture, No:0787 | D42: Nguyệt | E42: Hằng
A43: 46121.002 | B43: 3010101158001001 | C43: Phần cứng thiết kế đồ họa: Z620 Workstation Intel Xeon E5-1650 3.20Ghz 12MB 1600 6C; 4GB DDR3-1600 (2x2GB) 1CPU RAM; NVIDIA Quadro 4000 2GB Graphics; 1TB 7200 RPM SATA HDD; 16X SuperMulti DVDRW SATA; Windows 7 Pro Edition 64bit; bàn phím, chuột, Model:HP-Z620, No:SGH341TSL1 | D43: Giường | E43: Thanh | F43: Thiết bị
A44: 46121.009 | B44: 3010102337034 | C44: Máy tính desktop Dell | D44: Toilet | E44: Quân | F44: CCDC
A45: 46121.036 | B45: 3010101086001 | C45: Máy chủ quản lý dữ liệu File server -Media File Directory server, MediaLibrary File Directory Server, consists of redundant pair of servers, heartbeat interconnect cables, documentation, software. For use with MediaLibrary 24000e or MediaLibrary ML1G (1 bộ gồm 02 cái), Model:TLA-5001-00, No:BZDR72550962, BZDR72652478 | D45: Phuc | E45: Banh | F45: Thiết bị

Sheet Main-sau thanh ly
C1: Đài Truyền Hình TPHCM
C2: Trung Tâm Phát hình
F4: BIÊN BẢN BÀN GIAO QUẢN LÝ TÀI SẢN
A6: STT | B6: Số chứng từ | C6: Ngày chứng từ | D6: Số hiệu cũ | E6: Số hiệu | F6: Tên tài sản | G6: Nước SX | H6: ĐVT | I6: SL | J6: Giá trị | K6: Phòng | L6: Người QL | M6: Vị trí
A7: 3 | B7: 77/2009 | C7: 40178 | E7: 3010101064002 | F7: Server Capture Digital Future theo định dạng DV và MPEG-2 , Model:i-Capture, No:0787 | G7: Việt Nam | H7: Bộ | I7: 1 | J7: 224486622 | K7: PH | L7: Lam | M7: Máy VP trong lầu 1 PH mới
A8: 3.1 | E8: 3010101064002001 | F8: Màn hình vi tính LCD Viewsonic 17", Model:VA1916W, No:RN7094300049 | I8: 1 | J8: 0 | K8: PH | L8: Lam
A9: 5 | B9: 03 DA/2011 | C9: 40875 | E9: 3010101086001 | F9: Máy chủ quản lý dữ liệu File server -Media File Directory server, MediaLibrary File Directory Server, consists of redundant pair of servers, heartbeat interconnect cables, documentation, software. For use with MediaLibrary 24000e or MediaLibrary ML1G (1 bộ gồm 02 cái), Model:TLA-5001-00, No:BZDR72550962, BZDR72652478 | G9: Mỹ | H9: Bộ | I9: 1 | J9: 367831511 | K9: PH | L9: Khanh | M9: BZDR72652478 (PM.mới) Webserver cũ BZDR72550962 (PM.cũ)
A10: 6 | B10: 03 DA/2011 | C10: 40875 | E10: 3010101087001 | F10: Máy tính điều khiển tủ: PCS Server | H10: Bộ | I10: 1 | J10: 317721303 | K10: PH | L10: Khanh | M10: PM.CŨ Sony Petasite
A11: 6.1 | E11: 3010101087001001 | F11: Máy tính điều khiển tủ: PCS Server'. CPU Quad Core Xeon 5420 (2.50GHz). 'Memory: 2 GB Memory Kit. 'FDD: 1 x FDD, HP 2x 146GB SAS 10K 2.5 DP HDD, 'Optical Drive: 1 x DVD-ROM, 'Keyboard and Mouse. 'Redundant P/S: 1 Redundant Power Supply và phần mềm , Model:DL 360G5, No:SGH848XNAT | I11: 1 | J11: 243712689 | K11: PH | L11: Khanh
A12: 6.2 | E12: 3010101087001002 | F12: 17" LCD Monitor, Model:L1710, No:3Xuân8294VN6 | I12: 1 | J12: 8407751 | K12: PH | L12: Khanh
A13: 7 | B13: 03 DA/2011 | C13: 40875 | E13: 3010101088001 | F13: Server hardware for database | H13: Bộ | I13: 1 | J13: 339581457 | K13: PH | L13: Khanh | M13: PM.MỚI SQL.BK
A14: 7.1 | E14: 3010101088001001 | F14: Monitor LCD 19", Model:L1910, No:CNC820PW49 | I14: 1 | J14: 14573436 | K14: PH | L14: Khanh
A15: 7.2 | E15: 3010101088001002 | F15: Server hardware for Database: Quad Core Xeon 5420 (2.50GHz), RAM 2GB, 2 x HP 146GB 10K SAS 2.5 DP HDD; HP Slim 8X/24X DVD-ROM Drive, FDDKeyboard and Mouse, Model:DL360G5, No:GH848XNAS | I15: 1 | J15: 166361375 | K15: PH | L15: Khanh
A16: 8 | B16: 03 DA/2011 | C16: 40875 | E16: 3010101088002 | F16: Server hardware for database | H16: Bộ | I16: 1 | J16: 339581457 | K16: PH | L16: Khanh | M16: PM.Mới SQL.Main
A17: 8.1 | E17: 3010101088002001 | F17: Monitor LCD 19", Model:L1910, No:CNC820PWBM | I17: 1 | J17: 14573436 | K17: PH | L17: Khanh
A18: 8.2 | E18: 3010101088002002 | F18: Server hardware for Database: Quad Core Xeon 5420 (2.50GHz), RAM 2GB, 2 x HP 146GB 10K SAS 2.5 DP HDD; HP Slim 8X/24X DVD-ROM Drive, FDDKeyboard and Mouse, Model:DL360G5, No:GH848XNAV | I18: 1 | J18: 166361375 | K18: PH | L18: Khanh
A19: 9 | B19: 03 DA/2011 | C19: 40875 | E19: 3010101089001 | F19: Hệ thống phần cứng | H19: Bộ | I19: 1 | J19: 209765774 | K19: PH | L19: Khanh | M19: Auto9B HTV9 Bkup, PM.cũ Rack 3
A20: 9.1 | E20: 3010101089001001 | F20: PC hardware for Automation: Xeon 5450 3.00 12M/1333 QC, NVIDIA Quadro FX3700 512MB PCIe GraphicsHP 4GB (2x2GB) DDR2-667 ECC FBD RAM; HP 250GB SATA 3Gb/s . NXuân 7200 1st HDD; HP USB Standard Keyboard; HP USB Optical Scroll Mouse, HP 16X DVD+-RW SuperMulti SATA 1st Drive; Floppy Disk Drive, Model:XW8600, No:SGH85101P2 | I20: 1 | J20: 129591475 | K20: PH | L20: Khanh
A21: 9.2 | E21: 3010101089001002 | F21: 19" LCD monitor, Model:L-1910, No:CNC820PW40 | I21: 1 | J21: 14573436 | K21: PH | L21: Khanh
A22: 10 | B22: 03 DA/2011 | C22: 40875 | E22: 3010101089002 | F22: Hệ thống phần cứng | H22: Bộ | I22: 1 | J22: 209765774 | K22: PH | L22: Khanh | M22: PM.Mới
A23: 10.1 | E23: 3010101089002001 | F23: PC hardware for Automation: Xeon 5450 3.00 12M/1333 QC, NVIDIA Quadro FX3700 512MB PCIe GraphicsHP 4GB (2x2GB) DDR2-667 ECC FBD RAM; HP 250GB SATA 3Gb/s . NXuân 7200 1st HDD; HP USB Standard Keyboard; HP USB Optical Scroll Mouse, HP 16X DVD+-RW SuperMulti SATA 1st Drive; Floppy Disk Drive, Model:XW8600, No:SGH85101P1 | I23: 1 | J23: 129591475 | K23: PH | L23: Khanh
A24: 10.2 | E24: 3010101089002002 | F24: 19" LCD monitor, Model:L-1910, No:CNC820PWBL | I24: 1 | J24: 14573436 | K24: PH | L24: Khanh
A25: 11 | B25: 03 DA/2011 | C25: 40875 | E25: 3010101089003 | F25: Hệ thống phần cứng | H25: Bộ | I25: 1 | J25: 209765774 | K25: PH | L25: Khanh | M25: Kho Lầu 2
A26: 11.1 | E26: 3010101089003001 | F26: PC hardware for Automation: Xeon 5450 3.00 12M/1333 QC, NVIDIA Quadro FX3700 512MB PCIe GraphicsHP 4GB (2x2GB) DDR2-667 ECC FBD RAM; HP 250GB SATA 3Gb/s . NXuân 7200 1st HDD; HP USB Standard Keyboard; HP USB Optical Scroll Mouse, HP 16X DVD+-RW SuperMulti SATA 1st Drive; Floppy Disk Drive, Model:XW8600, No:SGH85101P5 | I26: 1 | J26: 129591475 | K26: PH | L26: Khanh
A27: 11.2 | E27: 3010101089003002 | F27: 19" LCD monitor, Model:L-1910, No:CNC820PW43 | I27: 1 | J27: 14573436 | K27: PH | L27: Khanh
A28: 12 | B28: 03 DA/2011 | C28: 40875 | E28: 3010101089005 | F28: Hệ thống phần cứng | H28: Bộ | I28: 1 | J28: 209765774 | K28: PH | L28: Khanh | M28: PM.mới
A29: 12.1 | E29: 3010101089005001 | F29: PC hardware for Automation: Xeon 5450 3.00 12M/1333 QC, NVIDIA Quadro FX3700 512MB PCIe GraphicsHP 4GB (2x2GB) DDR2-667 ECC FBD RAM; HP 250GB SATA 3Gb/s . NXuân 7200 1st HDD; HP USB Standard Keyboard; HP USB Optical Scroll Mouse, HP 16X DVD+-RW SuperMulti SATA 1st Drive; Floppy Disk Drive, Model:XW8600, No:SGH85101P3 | I29: 1 | J29: 129591475 | K29: PH | L29: Khanh
A30: 13 | B30: 03 DA/2011 | C30: 40875 | E30: 3010101089006 | F30: Hệ thống phần cứng | H30: Bộ | I30: 1 | J30: 209765775 | K30: PH | L30: Khanh | M30: PM.mới
A31: 13.1 | E31: 3010101089006001 | F31: PC hardware for Automation: Xeon 5450 3.00 12M/1333 QC, NVIDIA Quadro FX3700 512MB PCIe GraphicsHP 4GB (2x2GB) DDR2-667 ECC FBD RAM; HP 250GB SATA 3Gb/s . NXuân 7200 1st HDD; HP USB Standard Keyboard; HP USB Optical Scroll Mouse, HP 16X DVD+-RW SuperMulti SATA 1st Drive; Floppy Disk Drive, Model:XW8600, No:SGH85101P6 | I31: 1 | J31: 129591475 | K31: PH | L31: Khanh
A32: 14 | B32: 03 DA/2011 | C32: 40875 | E32: 3010101089008 | F32: Hệ thống phần cứng | H32: Bộ | I32: 1 | J32: 105621760 | K32: PH | L32: Khanh | M32: ingest 1, Kho Lầu 1
A33: 14.1 | E33: 3010101089008001 | F33: PC hardware for AutomationPentium Dual Core E2200 2.2GHz/ G33 Express Chipset/(2* 512MB)=1GB DDR2 800Mhz SDRAM/ 160GB SATA/ DVD R/W+/ No FDD, Win Vista Biz License Preloaded with Win XP Professional, mouse and keyboard, Model:DX2710, No:SGH90307TC | I33: 1 | J33: 31613146 | K33: PH | L33: Khanh
A34: 15 | B34: 03 DA/2011 | C34: 40875 | E34: 3010101089014 | F34: Hệ thống phần cứng | H34: Bộ | I34: 1 | J34: 105621760 | K34: PH | L34: Khanh | M34: Alarm K79, phía sau máy VP1
A35: 15.1 | E35: 3010101089014001 | F35: PC hardware for AutomationPentium Dual Core E2200 2.2GHz/ G33 Express Chipset/(2* 512MB)=1GB DDR2 800Mhz SDRAM/ 160GB SATA/ DVD R/W+/ No FDD, Win Vista Biz License Preloaded with Win XP Professional, mouse and keyboard, Model:DX2710, No:SGH9040CY7 | I35: 1 | J35: 31613146 | K35: PH | L35: Khanh
A36: 15.2 | E36: 3010101089014002 | F36: 17" LCD monitor, Model:L1710, No:3Xuân8294VMX | I36: 1 | J36: 8407752 | K36: PH | L36: Khanh
A37: 16 | B37: 03 DA/2011 | C37: 40875 | E37: 3010101090006 | F37: PC hardware for Traffic management | H37: Bộ | I37: 1 | J37: 40020897 | K37: PH | L37: Khanh | M37: upload 1, Phòng PH
A38: 16.1 | E38: 3010101090006001 | F38: PC hardware for Traffic managementPentium Dual Core E2200 2.2GHz/ G33 Express Chipset/ (2*512MB) =1GB DDR2 800Mhz SDRAM/ 160GB SATA/ DVD R/W+/ No FDD, Win Vista Biz License Preloaded with Win XP Professional, mouse and keyboard, Model:DX2710, No:SGH90307S4 | I38: 1 | J38: 31613145 | K38: PH | L38: Khanh
A39: 16.2 | E39: 3010101090006002 | F39: 17" LCD monitor, Model:L1710, No:3Xuân8294VMQ | I39: 1 | J39: 8407752 | K39: PH | L39: Khanh
A40: 17 | B40: 03 DA/2011 | C40: 40875 | E40: 3010101090007 | F40: PC hardware for Traffic management | H40: Bộ | I40: 1 | J40: 105621760 | K40: PH | L40: Hải | M40: PM.mới
A41: 17.1 | E41: 3010101090007001 | F41: PC hardware for Traffic managementPentium Dual Core E2200 2.2GHz/ G33 Express Chipset/ (2*512MB) =1GB DDR2 800Mhz SDRAM/ 160GB SATA/ DVD R/W+/ No FDD, Win Vista Biz License Preloaded with Win XP Professional, mouse and keyboard, Model:DX2710, No:SGH9040CXJ | I41: 1 | J41: 31613145 | K41: PH | L41: Hải
A42: 17.2 | E42: 3010101090007002 | F42: 17" LCD monitor, Model:L1710, No:3Xuân8294VN5 | I42: 1 | J42: 8407752 | K42: PH | L42: Hải
...

Sheet Sheet1 (2)
C1: Đài Truyền Hình TPHCM
C2: Trung Tâm Phát hình
F4: BIÊN BẢN BÀN GIAO QUẢN LÝ TÀI SẢN
A6: STT | B6: Số chứng từ | C6: Ngày chứng từ | D6: Số hiệu cũ | E6: Số hiệu | F6: Tên tài sản | G6: Nước SX | H6: ĐVT | I6: SL | J6: Giá trị | K6: Phòng | L6: Người QL | M6: Vị trí
A7: 1 | B7: 04DA/2009 | C7: 40024 | E7: 3010101052001 | F7: Bộ Prompter Control và Tele-prompter | H7: Bộ | I7: 1 | J7: 593040360 | K7: KT | L7: CUONG | M7: máy tính Cường ngồi, chờ Thanh lý
A8: 1.1 | E8: 3010101052001001 | F8: Máy vi tính, Rackmount Kit:Intel PD 925 (3.0/800/2x2MB), 256 MB PC2-5300 (DDR2-667), 80GB SATA 3.0Gb/s, Integrated Broadcom NetXtreme Gigabit Ethernet NIC, Free DOS software, FDD 1.44MB., Model:DC5700, No:SGH7040B7R | I8: 1 | J8: 0 | K8: KT | L8: CUONG | M8: F2b
A9: 1.2 | E9: 3010101052001002 | F9: Màn hình 17", No:CNN7022TQR | I9: 1 | J9: 0 | K9: KT | L9: CUONG | M9: F2b
A10: 1.3 | E10: 3010101052001003 | F10: 15" TFT Flat screen On-Camera monitor inclusive Integral Cue Light & external, Standard Hood with glass & light shield, 'Light weight Adjustable Mounting plate MT/RED, PCI Promptcard with Newsroom interface Winplus & Opto Desk Top Hand Control PCI/WIN/HCI. | I10: 1 | J10: 0 | K10: KT | L10: CUONG | M10: F2b
A11: 2 | B11: 77/2009 | C11: 40178 | E11: 3010101064001 | F11: Server Capture Digital Future theo định dạng DV và MPEG-2 , Model:i-Capture, No:0786 | G11: Việt Nam | H11: Bộ | I11: 1 | J11: 224486622 | K11: KT | L11: THANH | M11: F1 RACK 1
A12: 2.1 | E12: 3010101064001001 | F12: Màn hình vi tính LCD Viewsonic 17", Model:VA1916W, No:RN7094300833 | I12: 1 | J12: 0 | K12: KT | L12: THANH
A13: 3 | B13: 77/2009 | C13: 40178 | E13: 3010101064002 | F13: Server Capture Digital Future theo định dạng DV và MPEG-2 , Model:i-Capture, No:0787 | G13: Việt Nam | H13: Bộ | I13: 1 | J13: 224486622 | K13: PH | L13: Lam | M13: Máy VP trong lầu 1 PH mới
A14: 3.1 | E14: 3010101064002001 | F14: Màn hình vi tính LCD Viewsonic 17", Model:VA1916W, No:RN7094300049 | I14: 1 | J14: 0 | K14: PH | L14: Lam
A15: 4 | B15: 15/2011 | C15: 40702 | E15: 3010101077001 | F15: Hệ thống chạy chữ Autoscript, Model:TFT15-ELP, No:15E2101005 | G15: Anh | H15: Bộ | I15: 1 | J15: 385639606 | K15: KT | L15: HAN | M15: F2B
A16: 4.1 | E16: 3010101077001001 | F16: Máy vi tính chạy chữ Việt Đông | I16: 1 | J16: 12894230 | K16: KT | L16: HAN | M16: F2B
A17: 4.2 | E17: 3010101077001002 | F17: Màn hình LCD 17" HP, Model:LE1711, No:3Xuân00113W5 | I17: 1 | J17: 0 | K17: KT | L17: HAN | M17: F2B
A18: 5 | B18: 03 DA/2011 | C18: 40875 | E18: 3010101086001 | F18: Máy chủ quản lý dữ liệu File server -Media File Directory server, MediaLibrary File Directory Server, consists of redundant pair of servers, heartbeat interconnect cables, documentation, software. For use with MediaLibrary 24000e or MediaLibrary ML1G (1 bộ gồm 02 cái), Model:TLA-5001-00, No:BZDR72550962, BZDR72652478 | G18: Mỹ | H18: Bộ | I18: 1 | J18: 367831511 | K18: PH | L18: Khanh | M18: BZDR72652478 (PM.mới) Webserver cũ BZDR72550962 (PM.cũ)
A19: 6 | B19: 03 DA/2011 | C19: 40875 | E19: 3010101087001 | F19: Máy tính điều khiển tủ: PCS Server | H19: Bộ | I19: 1 | J19: 317721303 | K19: PH | L19: Khanh | M19: PM.CŨ Sony Petasite
A20: 6.1 | E20: 3010101087001001 | F20: Máy tính điều khiển tủ: PCS Server'. CPU Quad Core Xeon 5420 (2.50GHz). 'Memory: 2 GB Memory Kit. 'FDD: 1 x FDD, HP 2x 146GB SAS 10K 2.5 DP HDD, 'Optical Drive: 1 x DVD-ROM, 'Keyboard and Mouse. 'Redundant P/S: 1 Redundant Power Supply và phần mềm , Model:DL 360G5, No:SGH848XNAT | I20: 1 | J20: 243712689 | K20: PH | L20: Khanh
A21: 6.2 | E21: 3010101087001002 | F21: 17" LCD Monitor, Model:L1710, No:3Xuân8294VN6 | I21: 1 | J21: 8407751 | K21: PH | L21: Khanh
A22: 7 | B22: 03 DA/2011 | C22: 40875 | E22: 3010101088001 | F22: Server hardware for database | H22: Bộ | I22: 1 | J22: 339581457 | K22: PH | L22: Khanh | M22: PM.MỚI SQL.BK
A23: 7.1 | E23: 3010101088001001 | F23: Monitor LCD 19", Model:L1910, No:CNC820PW49 | I23: 1 | J23: 14573436 | K23: PH | L23: Khanh
A24: 7.2 | E24: 3010101088001002 | F24: Server hardware for Database: Quad Core Xeon 5420 (2.50GHz), RAM 2GB, 2 x HP 146GB 10K SAS 2.5 DP HDD; HP Slim 8X/24X DVD-ROM Drive, FDDKeyboard and Mouse, Model:DL360G5, No:GH848XNAS | I24: 1 | J24: 166361375 | K24: PH | L24: Khanh
A25: 8 | B25: 03 DA/2011 | C25: 40875 | E25: 3010101088002 | F25: Server hardware for database | H25: Bộ | I25: 1 | J25: 339581457 | K25: PH | L25: Khanh | M25: PM.Mới SQL.Main
A26: 8.1 | E26: 3010101088002001 | F26: Monitor LCD 19", Model:L1910, No:CNC820PWBM | I26: 1 | J26: 14573436 | K26: PH | L26: Khanh
A27: 8.2 | E27: 3010101088002002 | F27: Server hardware for Database: Quad Core Xeon 5420 (2.50GHz), RAM 2GB, 2 x HP 146GB 10K SAS 2.5 DP HDD; HP Slim 8X/24X DVD-ROM Drive, FDDKeyboard and Mouse, Model:DL360G5, No:GH848XNAV | I27: 1 | J27: 166361375 | K27: PH | L27: Khanh
A28: 9 | B28: 03 DA/2011 | C28: 40875 | E28: 3010101089001 | F28: Hệ thống phần cứng | H28: Bộ | I28: 1 | J28: 209765774 | K28: PH | L28: Khanh | M28: Auto9B HTV9 Bkup, PM.cũ Rack 3
A29: 9.1 | E29: 3010101089001001 | F29: PC hardware for Automation: Xeon 5450 3.00 12M/1333 QC, NVIDIA Quadro FX3700 512MB PCIe GraphicsHP 4GB (2x2GB) DDR2-667 ECC FBD RAM; HP 250GB SATA 3Gb/s . NXuân 7200 1st HDD; HP USB Standard Keyboard; HP USB Optical Scroll Mouse, HP 16X DVD+-RW SuperMulti SATA 1st Drive; Floppy Disk Drive, Model:XW8600, No:SGH85101P2 | I29: 1 | J29: 129591475 | K29: PH | L29: Khanh
A30: 9.2 | E30: 3010101089001002 | F30: 19" LCD monitor, Model:L-1910, No:CNC820PW40 | I30: 1 | J30: 14573436 | K30: PH | L30: Khanh
A31: 10 | B31: 03 DA/2011 | C31: 40875 | E31: 3010101089002 | F31: Hệ thống phần cứng | H31: Bộ | I31: 1 | J31: 209765774 | K31: PH | L31: Khanh | M31: PM.Mới
A32: 10.1 | E32: 3010101089002001 | F32: PC hardware for Automation: Xeon 5450 3.00 12M/1333 QC, NVIDIA Quadro FX3700 512MB PCIe GraphicsHP 4GB (2x2GB) DDR2-667 ECC FBD RAM; HP 250GB SATA 3Gb/s . NXuân 7200 1st HDD; HP USB Standard Keyboard; HP USB Optical Scroll Mouse, HP 16X DVD+-RW SuperMulti SATA 1st Drive; Floppy Disk Drive, Model:XW8600, No:SGH85101P1 | I32: 1 | J32: 129591475 | K32: PH | L32: Khanh
A33: 10.2 | E33: 3010101089002002 | F33: 19" LCD monitor, Model:L-1910, No:CNC820PWBL | I33: 1 | J33: 14573436 | K33: PH | L33: Khanh
A34: 11 | B34: 03 DA/2011 | C34: 40875 | E34: 3010101089003 | F34: Hệ thống phần cứng | H34: Bộ | I34: 1 | J34: 209765774 | K34: PH | L34: Khanh | M34: Kho Lầu 2
A35: 11.1 | E35: 3010101089003001 | F35: PC hardware for Automation: Xeon 5450 3.00 12M/1333 QC, NVIDIA Quadro FX3700 512MB PCIe GraphicsHP 4GB (2x2GB) DDR2-667 ECC FBD RAM; HP 250GB SATA 3Gb/s . NXuân 7200 1st HDD; HP USB Standard Keyboard; HP USB Optical Scroll Mouse, HP 16X DVD+-RW SuperMulti SATA 1st Drive; Floppy Disk Drive, Model:XW8600, No:SGH85101P5 | I35: 1 | J35: 129591475 | K35: PH | L35: Khanh
A36: 11.2 | E36: 3010101089003002 | F36: 19" LCD monitor, Model:L-1910, No:CNC820PW43 | I36: 1 | J36: 14573436 | K36: PH | L36: Khanh
A37: 12 | B37: 03 DA/2011 | C37: 40875 | E37: 3010101089005 | F37: Hệ thống phần cứng | H37: Bộ | I37: 1 | J37: 209765774 | K37: PH | L37: Khanh | M37: PM.mới
A38: 12.1 | E38: 3010101089005001 | F38: PC hardware for Automation: Xeon 5450 3.00 12M/1333 QC, NVIDIA Quadro FX3700 512MB PCIe GraphicsHP 4GB (2x2GB) DDR2-667 ECC FBD RAM; HP 250GB SATA 3Gb/s . NXuân 7200 1st HDD; HP USB Standard Keyboard; HP USB Optical Scroll Mouse, HP 16X DVD+-RW SuperMulti SATA 1st Drive; Floppy Disk Drive, Model:XW8600, No:SGH85101P3 | I38: 1 | J38: 129591475 | K38: PH | L38: Khanh
A39: 13 | B39: 03 DA/2011 | C39: 40875 | E39: 3010101089006 | F39: Hệ thống phần cứng | H39: Bộ | I39: 1 | J39: 209765775 | K39: PH | L39: Khanh | M39: PM.mới
A40: 13.1 | E40: 3010101089006001 | F40: PC hardware for Automation: Xeon 5450 3.00 12M/1333 QC, NVIDIA Quadro FX3700 512MB PCIe GraphicsHP 4GB (2x2GB) DDR2-667 ECC FBD RAM; HP 250GB SATA 3Gb/s . NXuân 7200 1st HDD; HP USB Standard Keyboard; HP USB Optical Scroll Mouse, HP 16X DVD+-RW SuperMulti SATA 1st Drive; Floppy Disk Drive, Model:XW8600, No:SGH85101P6 | I40: 1 | J40: 129591475 | K40: PH | L40: Khanh
A41: 14 | B41: 03 DA/2011 | C41: 40875 | E41: 3010101089008 | F41: Hệ thống phần cứng | H41: Bộ | I41: 1 | J41: 105621760 | K41: PH | L41: Khanh | M41: ingest 1, Kho Lầu 1
A42: 14.1 | E42: 3010101089008001 | F42: PC hardware for AutomationPentium Dual Core E2200 2.2GHz/ G33 Express Chipset/(2* 512MB)=1GB DDR2 800Mhz SDRAM/ 160GB SATA/ DVD R/W+/ No FDD, Win Vista Biz License Preloaded with Win XP Professional, mouse and keyboard, Model:DX2710, No:SGH90307TC | I42: 1 | J42: 31613146 | K42: PH | L42: Khanh
...

Sheet Tai san thanh ly den 31.12.2020
A3: 679 | B3: 23/2012 | C3: 41044 | E3: 302099910010002 | F3: Tivi full HD 46" Sony, Model:KDL-46EX710, No:1007486 | G3: Malaysia | H3: Cái | I3: 1 | J3: 51460000 | K3: MCR | L3: Thịnh | M3: P.CƠ ĐIỆN | O3: Đã chuyển cơ điện, không có trong file tài sản mới ngày 11/5/2021

Sheet TS them den 31.12.2020

Sheet TS Thêm đến 31.12.2021
A1: 139 | B1: 0012GTTS/AR/DV09/2021 | C1: 44515 | E1: 3010102371008 | F1: Bộ máy tính Digital Future (máy ghi phát file 2 kênh, không kèm màn hình), Model:i-DDR, No:160321C01 | G1: Việt Nam | H1: Bộ | I1: 1 | J1: 272000000
A2: 140 | B2: 0012GTTS/AR/DV09/2021 | C2: 44515 | E2: 3010102371009 | F2: Bộ máy tính Digital Future (máy ghi phát file 2 kênh, không kèm màn hình), Model:i-DDR, No:160321C02 | G2: Việt Nam | H2: Bộ | I2: 1 | J2: 272000000
